Workbook

Sheet Valuation>
B3: CF | C3: Dividend & Buyback Data
B4: Growth | C4: Index Returns
B5: Rf | C5: 10Y Bond Data - Default Spread
B6: ERP | C6: Market Premia

Sheet Valuation
B2: Valuation of S&P 500 | E2: =SUM(E19:E29) -> 11301.819 | M2: Yield | N2: EPS Growth | O2: Rf | P2: ERP
M3: 20 Yrs | N3: 3 Years | O3: 50 Yrs | P3: 15 Years
E4: =IF(OR(C8="",C9="",C10="",C11="",C12=""),"Enter Key Inputs",IF(E2>1.05*C8,"Undervalued",IF(E2<0.95*C8,"Overvalued","Fairly Valued"))) -> Undervalued | M4: 15 Yrs | N4: 5 Years | O4: 30 Yrs | P4: 7 Years
B5: Particulars | C5: Key Inputs | D5: Assumptions | M5: 10 Yrs | N5: 7 Years | O5: 20 Yrs | P5: 5 Years
M6: 7 Yrs | N6: 10 Years | O6: 15 Yrs | P6: 3 Years
B7: Date | C7: =TODAY() -> 46107 | D7: =C7 -> 46107 | E7: =IF(OR(C8="",C9="",C10="",C11="",C12=""),"Provide Key Inputs","The Market implied fair value of S&P 500 is "&ROUNDUP(E2,0)&". The S&P 500 is currently trading at "&ROUNDUP(D8,0)&". A "&TEXT(ABS((D8-E2)/D8),"0.00%")&" "&IF(E4="Undervalued","appreciation",IF(E4="Overvalued","Correction","Adjustment"))&" expected from this level.") -> The Market implied fair value of S&P 500 is 11302. The S&P 500 is currently trading at 6901. A 63.77% appreciation expected from this level. | M7: 5 Yrs | O7: 7 Yrs | P7: Latest
B8: Current S&P 500 Level | C8: 6901 | D8: =C8 -> 6901 | M8: 3 Yrs | O8: 5 Yrs
B9: Total Yield | C9: 20 Yrs | D9: =VLOOKUP(C9,'Exp. Div&BB'!J3:K13,2,FALSE) -> 0.047289804 | O9: Latest
B10: Expected Growth | C10: 10 Years | D10: =VLOOKUP(C10,'S&P 500 EPS Growth'!L4:M10,2,FALSE) -> 0.083206427
B11: Risk- Free Rate | C11: Latest | D11: =VLOOKUP(C11,'Rf Historical'!J4:K16,2,FALSE) -> 0.042479091
B12: Equity Risk Premium | C12: Latest | D12: =VLOOKUP(C12,'ERP Historical'!G4:H12,2,FALSE) -> 0.0198
B13: Cost of Equity | D13: =D11+D12 -> 0.062279091
B14: Teminal Growth | D14: 0.01
B16: Year | C16: Expected Dividend & Buy Backs | D16: Cummulative PV Factor (Cost of Equity) | E16: Present Value of Expected Div & Buybacks
B19: 2025 | C19: =$D$8*$D$9*(1+$D$10)^(B19-($B$19-1)) -> 353.5011 | D19: =1/(1+$D$13)^(B19-($B$19-1)) -> 0.9413722 | E19: =C19*D19 -> 332.77611
B20: =B19+1 -> 2026 | C20: =$D$8*$D$9*(1+$D$10)^(B20-($B$19-1)) -> 382.91466 | D20: =1/(1+$D$13)^(B20-($B$19-1)) -> 0.88618161 | E20: =C20*D20 -> 339.33193
B21: =B20+1 -> 2027 | C21: =$D$8*$D$9*(1+$D$10)^(B21-($B$19-1)) -> 414.77563 | D21: =1/(1+$D$13)^(B21-($B$19-1)) -> 0.83422673 | E21: =C21*D21 -> 346.01691
B22: =B21+1 -> 2028 | C22: =$D$8*$D$9*(1+$D$10)^(B22-($B$19-1)) -> 449.28762 | D22: =1/(1+$D$13)^(B22-($B$19-1)) -> 0.78531785 | E22: =C22*D22 -> 352.83359
B23: =B22+1 -> 2029 | C23: =$D$8*$D$9*(1+$D$10)^(B23-($B$19-1)) -> 486.67124 | D23: =1/(1+$D$13)^(B23-($B$19-1)) -> 0.73927639 | E23: =C23*D23 -> 359.78456
B24: =B23+1 -> 2030 | C24: =$D$8*$D$9*(1+$D$10)^(B24-($B$19-1)) -> 527.16542 | D24: =1/(1+$D$13)^(B24-($B$19-1)) -> 0.69593423 | E24: =C24*D24 -> 366.87246
B25: =B24+1 -> 2031 | C25: =$D$8*$D$9*(1+$D$10)^(B25-($B$19-1)) -> 571.02897 | D25: =1/(1+$D$13)^(B25-($B$19-1)) -> 0.65513314 | E25: =C25*D25 -> 374.1
B26: =B25+1 -> 2032 | C26: =$D$8*$D$9*(1+$D$10)^(B26-($B$19-1)) -> 618.54225 | D26: =1/(1+$D$13)^(B26-($B$19-1)) -> 0.61672412 | E26: =C26*D26 -> 381.46992
B27: =B26+1 -> 2033 | C27: =$D$8*$D$9*(1+$D$10)^(B27-($B$19-1)) -> 670.00894 | D27: =1/(1+$D$13)^(B27-($B$19-1)) -> 0.58056694 | E27: =C27*D27 -> 388.98504
B28: =B27+1 -> 2034 | C28: =$D$8*$D$9*(1+$D$10)^(B28-($B$19-1)) -> 725.75799 | D28: =1/(1+$D$13)^(B28-($B$19-1)) -> 0.54652957 | E28: =C28*D28 -> 396.6482
B29: 2034-Ꝏ | C29: =(C28*(1+D14))/(D13-D14) -> 14021.2 | D29: =D28 -> 0.54652957 | E29: =C29*D29 -> 7663.0002

Sheet Data>

Sheet Exp. Div&BB
B2: Year | C2: S&P 500 Range | D2: Dividend | E2: Buybacks | F2: Total Earnings | G2: S&P 500 Earnings Yield
B3: 2000 | C3: =VLOOKUP(B3,'S&P 500 Historical'!$H$2:$J$28,2,FALSE) -> 1419.7333 | D3: 16.27 | E3: 14.8 | F3: =D3+E3 -> 31.07 | G3: =F3/C3 -> 0.021884391 | I3: Average S&P 500 Earning Yield- | J3: 20 Yrs | K3: =AVERAGE(G9:G28) -> 0.047289804
B4: =B3+1 -> 2001 | C4: =VLOOKUP(B4,'S&P 500 Historical'!$H$2:$J$28,2,FALSE) -> 1185.75 | D4: 15.74 | E4: 14.34 | F4: =D4+E4 -> 30.08 | G4: =F4/C4 -> 0.025367911
B5: =B4+1 -> 2002 | C5: =VLOOKUP(B5,'S&P 500 Historical'!$H$2:$J$28,2,FALSE) -> 988.58333 | D5: 16.08 | E5: 13.75 | F5: =D5+E5 -> 29.83 | G5: =F5/C5 -> 0.030174492 | I5: Average S&P 500 Earning Yield- | J5: 15 Yrs | K5: =AVERAGE(G14:G28) -> 0.045443275
B6: =B5+1 -> 2003 | C6: =VLOOKUP(B6,'S&P 500 Historical'!$H$2:$J$28,2,FALSE) -> 967.925 | D6: 17.88 | E6: 13.7 | F6: =D6+E6 -> 31.58 | G6: =F6/C6 -> 0.032626495
B7: =B6+1 -> 2004 | C7: =VLOOKUP(B7,'S&P 500 Historical'!$H$2:$J$28,2,FALSE) -> 1133.95 | D7: 19.407 | E7: 21.193 | F7: =D7+E7 -> 40.6 | G7: =F7/C7 -> 0.035804048 | I7: Average S&P 500 Earning Yield- | J7: 10 Yrs | K7: =AVERAGE(G19:G28) -> 0.041375961
B8: =B7+1 -> 2005 | C8: =VLOOKUP(B8,'S&P 500 Historical'!$H$2:$J$28,2,FALSE) -> 1207.7667 | D8: 22.38 | E8: 38.79 | F8: =D8+E8 -> 61.17 | G8: =F8/C8 -> 0.0506472
B9: =B8+1 -> 2006 | C9: =VLOOKUP(B9,'S&P 500 Historical'!$H$2:$J$28,2,FALSE) -> 1318.3 | D9: 25.05 | E9: 48.11 | F9: =D9+E9 -> 73.16 | G9: =F9/C9 -> 0.055495714 | I9: Average S&P 500 Earning Yield- | J9: 7 Yrs | K9: =AVERAGE(G22:G28) -> 0.038332904
B10: =B9+1 -> 2007 | C10: =VLOOKUP(B10,'S&P 500 Historical'!$H$2:$J$28,2,FALSE) -> 1478.1 | D10: 27.73 | E10: 67.63 | F10: =D10+E10 -> 95.36 | G10: =F10/C10 -> 0.064515256
B11: =B10+1 -> 2008 | C11: =VLOOKUP(B11,'S&P 500 Historical'!$H$2:$J$28,2,FALSE) -> 1215.2167 | D11: 28.05 | E11: 39.47 | F11: =D11+E11 -> 67.52 | G11: =F11/C11 -> 0.055562108 | I11: Average S&P 500 Earning Yield- | J11: 5 Yrs | K11: =AVERAGE(G24:G28) -> 0.035476706
B12: =B11+1 -> 2009 | C12: =VLOOKUP(B12,'S&P 500 Historical'!$H$2:$J$28,2,FALSE) -> 948.51667 | D12: 22.31 | E12: 15.12 | F12: =D12+E12 -> 37.43 | G12: =F12/C12 -> 0.039461616
B13: =B12+1 -> 2010 | C13: =VLOOKUP(B13,'S&P 500 Historical'!$H$2:$J$28,2,FALSE) -> 1130.675 | D13: 23.12 | E13: 32.41 | F13: =D13+E13 -> 55.53 | G13: =F13/C13 -> 0.049112256 | I13: Average S&P 500 Earning Yield- | J13: 3 Yrs | K13: =AVERAGE(G26:G28) -> 0.032780212
B14: =B13+1 -> 2011 | C14: =VLOOKUP(B14,'S&P 500 Historical'!$H$2:$J$28,2,FALSE) -> 1280.75 | D14: 26.02 | E14: 45.26 | F14: =D14+E14 -> 71.28 | G14: =F14/C14 -> 0.05565489
B15: =B14+1 -> 2012 | C15: =VLOOKUP(B15,'S&P 500 Historical'!$H$2:$J$28,2,FALSE) -> 1386.5167 | D15: 30.44 | E15: 45.46 | F15: =D15+E15 -> 75.9 | G15: =F15/C15 -> 0.054741498
B16: =B15+1 -> 2013 | C16: =VLOOKUP(B16,'S&P 500 Historical'!$H$2:$J$28,2,FALSE) -> 1652.2917 | D16: 36.28 | E16: 51.85 | F16: =D16+E16 -> 88.13 | G16: =F16/C16 -> 0.053338041
B17: =B16+1 -> 2014 | C17: =VLOOKUP(B17,'S&P 500 Historical'!$H$2:$J$28,2,FALSE) -> 1944.415 | D17: 39.44 | E17: 62.54 | F17: =D17+E17 -> 101.98 | G17: =F17/C17 -> 0.052447651
B18: =B17+1 -> 2015 | C18: =VLOOKUP(B18,'S&P 500 Historical'!$H$2:$J$28,2,FALSE) -> 2051.9292 | D18: 43.16 | E18: 62.94 | F18: =D18+E18 -> 106.1 | G18: =F18/C18 -> 0.051707438
B19: =B18+1 -> 2016 | C19: =VLOOKUP(B19,'S&P 500 Historical'!$H$2:$J$28,2,FALSE) -> 2105.8283 | D19: 45.03 | E19: 63.64 | F19: =D19+E19 -> 108.67 | G19: =F19/C19 -> 0.051604396
B20: =B19+1 -> 2017 | C20: =VLOOKUP(B20,'S&P 500 Historical'!$H$2:$J$28,2,FALSE) -> 2465.2 | D20: 49.73 | E20: 58.55 | F20: =D20+E20 -> 108.28 | G20: =F20/C20 -> 0.043923414
B21: =B20+1 -> 2018 | C21: =VLOOKUP(B21,'S&P 500 Historical'!$H$2:$J$28,2,FALSE) -> 2738.3958 | D21: 53.61 | E21: 83.04 | F21: =D21+E21 -> 136.65 | G21: =F21/C21 -> 0.049901478
B22: =B21+1 -> 2019 | C22: =VLOOKUP(B22,'S&P 500 Historical'!$H$2:$J$28,2,FALSE) -> 2937.9617 | D22: 58.8 | E22: 91.7 | F22: =D22+E22 -> 150.5 | G22: =F22/C22 -> 0.051225992
B23: =B22+1 -> 2020 | C23: =VLOOKUP(B23,'S&P 500 Historical'!$H$2:$J$28,2,FALSE) -> 3216.9542 | D23: 56.7 | E23: 71.08 | F23: =D23+E23 -> 127.78 | G23: =F23/C23 -> 0.039720802
B24: =B23+1 -> 2021 | C24: =VLOOKUP(B24,'S&P 500 Historical'!$H$2:$J$28,2,FALSE) -> 4278.7583 | D24: 59.2 | E24: 88.04 | F24: =D24+E24 -> 147.24 | G24: =F24/C24 -> 0.034411852
B25: =B24+1 -> 2022 | C25: =VLOOKUP(B25,'S&P 500 Historical'!$H$2:$J$28,2,FALSE) -> 4077.655 | D25: 68.34 | E25: 113.65 | F25: =D25+E25 -> 181.99 | G25: =F25/C25 -> 0.044631044
... B28: =B27+1 -> 2025 | C28: =VLOOKUP(B28,'S&P 500 Historical'!$H$2:$J$28,2,FALSE) -> 6276.2992 | D28: 69.62632 | E28: 98.2 | F28: =D28+E28 -> 167.82632 | G28: =F28/C28 -> 0.026739694
B30: Source : Damodaran

Sheet S&P 500 EPS Growth
B2: Year | C2: S&P 500 Average Range | D2: P/E Ratio | E2: S&P 500 EPS | F2: EPS CAGR 3 Years | G2: EPS CAGR 5 Years | H2: EPS CAGR 7 Years | I2: EPS CAGR 10 Years
B3: 2000 | C3: 1419.7333 | D3: 27.491925 | E3: =C3/D3 -> 51.641831 | F3: - | G3: - | H3: - | I3: -
B4: 2001 | C4: 1185.75 | D4: 36.619217 | E4: =C4/D4 -> 32.38054 | F4: - | G4: - | H4: - | I4: - | K4: Average EPS CAGR - | L4: 3 Years | M4: =AVERAGE(F6:F28) -> 0.10577919
B5: 2002 | C5: 988.58333 | D5: 36.67725 | E5: =C5/D5 -> 26.953584 | F5: - | G5: - | H5: - | I5: -
B6: 2003 | C6: 967.925 | D6: 25.855617 | E6: =C6/D6 -> 37.435773 | F6: =_xlfn.RRI(3,E3,E6) -> -0.10168554 | G6: - | H6: - | I6: - | K6: Average EPS CAGR - | L6: 5 Years | M6: =AVERAGE(G8:G28) -> 0.087573006
B7: 2004 | C7: 1133.95 | D7: 20.246183 | E7: =C7/D7 -> 56.008087 | F7: =_xlfn.RRI(3,E4,E7) -> 0.20038959 | G7: - | H7: - | I7: -
B8: 2005 | C8: 1207.7667 | D8: 18.606983 | E8: =C8/D8 -> 64.909322 | F8: =_xlfn.RRI(3,E5,E8) -> 0.34038693 | G8: =_xlfn.RRI(5,E3,E8) -> 0.046793672 | H8: - | I8: - | K8: Average EPS CAGR - | L8: 7 Years | M8: =AVERAGE(H10:H28) -> 0.072321776
B9: 2006 | C9: 1318.3 | D9: 17.173958 | E9: =C9/D9 -> 76.76157 | F9: =_xlfn.RRI(3,E6,E9) -> 0.2704347 | G9: =_xlfn.RRI(5,E4,E9) -> 0.18842548 | H9: - | I9: -
B10: 2007 | C10: 1478.1 | D10: 19.0966 | E10: =C10/D10 -> 77.401213 | F10: =_xlfn.RRI(3,E7,E10) -> 0.11386445 | G10: =_xlfn.RRI(5,E5,E10) -> 0.23488424 | H10: =_xlfn.RRI(7,E3,E10) -> 0.059513735 | I10: - | K10: Average EPS CAGR - | L10: 10 Years | M10: =AVERAGE(I13:I28) -> 0.083206427
B11: 2008 | C11: 1215.2167 | D11: 34.402942 | E11: =C11/D11 -> 35.323045 | F11: =_xlfn.RRI(3,E8,E11) -> -0.18357363 | G11: =_xlfn.RRI(5,E6,E11) -> -0.011551 | H11: =_xlfn.RRI(7,E4,E11) -> 0.012502941 | I11: -
B12: 2009 | C12: 948.51667 | D12: 84.417542 | E12: =C12/D12 -> 11.236014 | F12: =_xlfn.RRI(3,E9,E12) -> -0.47298521 | G12: =_xlfn.RRI(5,E7,E12) -> -0.27477577 | H12: =_xlfn.RRI(7,E5,E12) -> -0.11750211 | I12: -
B13: 2010 | C13: 1130.675 | D13: 16.4049 | E13: =C13/D13 -> 68.923005 | F13: =_xlfn.RRI(3,E10,E13) -> -0.037932644 | G13: =_xlfn.RRI(5,E8,E13) -> 0.012072038 | H13: =_xlfn.RRI(7,E6,E13) -> 0.091109154 | I13: =_xlfn.RRI(10,E3,E13) -> 0.029286454
B14: 2011 | C14: 1280.75 | D14: 15.132292 | E14: =C14/D14 -> 84.636883 | F14: =_xlfn.RRI(3,E11,E14) -> 0.33813678 | G14: =_xlfn.RRI(5,E9,E14) -> 0.019725225 | H14: =_xlfn.RRI(7,E7,E14) -> 0.060756154 | I14: =_xlfn.RRI(10,E4,E14) -> 0.10084851
B15: 2012 | C15: 1386.5167 | D15: 15.874433 | E15: =C15/D15 -> 87.34275 | F15: =_xlfn.RRI(3,E12,E15) -> 0.98094096 | G15: =_xlfn.RRI(5,E10,E15) -> 0.024461919 | H15: =_xlfn.RRI(7,E8,E15) -> 0.043318992 | I15: =_xlfn.RRI(10,E5,E15) -> 0.12476303
B16: 2013 | C16: 1652.2917 | D16: 17.69895 | E16: =C16/D16 -> 93.35535 | F16: =_xlfn.RRI(3,E13,E16) -> 0.1064327 | G16: =_xlfn.RRI(5,E11,E16) -> 0.21455228 | H16: =_xlfn.RRI(7,E9,E16) -> 0.028352942 | I16: =_xlfn.RRI(10,E6,E16) -> 0.0956838
B17: 2014 | C17: 1944.415 | D17: 18.867533 | E17: =C17/D17 -> 103.05613 | F17: =_xlfn.RRI(3,E14,E17) -> 0.067836411 | G17: =_xlfn.RRI(5,E12,E17) -> 0.55773047 | H17: =_xlfn.RRI(7,E10,E17) -> 0.041743663 | I17: =_xlfn.RRI(10,E7,E17) -> 0.062875288
B18: 2015 | C18: 2051.9292 | D18: 22.157267 | E18: =C18/D18 -> 92.607504 | F18: =_xlfn.RRI(3,E15,E18) -> 0.019701612 | G18: =_xlfn.RRI(5,E13,E18) -> 0.060855899 | H18: =_xlfn.RRI(7,E11,E18) -> 0.14762048 | I18: =_xlfn.RRI(10,E8,E18) -> 0.036176912
B19: 2016 | C19: 2105.8283 | D19: 23.598867 | E19: =C19/D19 -> 89.234299 | F19: =_xlfn.RRI(3,E16,E19) -> -0.014936556 | G19: =_xlfn.RRI(5,E14,E19) -> 0.010635226 | H19: =_xlfn.RRI(7,E12,E19) -> 0.34449731 | I19: =_xlfn.RRI(10,E9,E19) -> 0.015170051
B20: 2017 | C20: 2465.2 | D20: 23.399825 | E20: =C20/D20 -> 105.35122 | F20: =_xlfn.RRI(3,E17,E20) -> 0.0073689741 | G20: =_xlfn.RRI(5,E15,E20) -> 0.038203616 | H20: =_xlfn.RRI(7,E13,E20) -> 0.062490485 | I20: =_xlfn.RRI(10,E10,E20) -> 0.03130988
B21: 2018 | C21: 2738.3958 | D21: 21.934625 | E21: =C21/D21 -> 124.84352 | F21: =_xlfn.RRI(3,E18,E21) -> 0.10468878 | G21: =_xlfn.RRI(5,E16,E21) -> 0.059852333 | H21: =_xlfn.RRI(7,E14,E21) -> 0.057097858 | I21: =_xlfn.RRI(10,E11,E21) -> 0.13456867
B22: 2019 | C22: 2937.9617 | D22: 21.673417 | E22: =C22/D22 -> 135.556 | F22: =_xlfn.RRI(3,E19,E22) -> 0.14955294 | G22: =_xlfn.RRI(5,E17,E22) -> 0.056352785 | H22: =_xlfn.RRI(7,E15,E22) -> 0.064805459 | I22: =_xlfn.RRI(10,E12,E22) -> 0.28277547
B23: 2020 | C23: 3216.9542 | D23: 31.511317 | E23: =C23/D23 -> 102.08885 | F23: =_xlfn.RRI(3,E20,E23) -> -0.010430599 | G23: =_xlfn.RRI(5,E18,E23) -> 0.019685934 | H23: =_xlfn.RRI(7,E16,E23) -> 0.012857725 | I23: =_xlfn.RRI(10,E13,E23) -> 0.040067228
B24: 2021 | C24: 4278.7583 | D24: 26.286208 | E24: =C24/D24 -> 162.77579 | F24: =_xlfn.RRI(3,E21,E24) -> 0.09246601 | G24: =_xlfn.RRI(5,E19,E24) -> 0.12774679 | H24: =_xlfn.RRI(7,E17,E24) -> 0.067479209 | I24: =_xlfn.RRI(10,E14,E24) -> 0.067586357
... B28: 2025 | C28: 6276.2992 | D28: 27.912836 | E28: =C28/D28 -> 224.85351 | F28: =_xlfn.RRI(3,E25,E28) -> 0.062636673 | G28: =_xlfn.RRI(5,E23,E28) -> 0.17107381 | H28: =_xlfn.RRI(7,E21,E28) -> 0.087689179 | I28: =_xlfn.RRI(10,E18,E28) -> 0.092761407
B31: Source : Macrotrends

Sheet S&P 500 Historical
B2: Date | C2: Close | D2: Monthly Returns | H2: Year | I2: Average Range | J2: Average Return
B3: 36526 | C3: 1394.5 | H3: 2000 | I3: =AVERAGEIFS($C$3:$C$314,$B$3:$B$314,">="&DATE(H3,1,1),$B$3:$B$314,"<="&DATE(H3,12,31)) -> 1419.7333
B4: 36557 | C4: 1366.4 | D4: =C4/C3-1 -> -0.020150592 | H4: =H3+1 -> 2001 | I4: =AVERAGEIFS($C$3:$C$314,$B$3:$B$314,">="&DATE(H4,1,1),$B$3:$B$314,"<="&DATE(H4,12,31)) -> 1185.75 | J4: =I4/I3-1 -> -0.16480795
B5: 36586 | C5: 1498.6 | D5: =C5/C4-1 -> 0.096750585 | H5: =H4+1 -> 2002 | I5: =AVERAGEIFS($C$3:$C$314,$B$3:$B$314,">="&DATE(H5,1,1),$B$3:$B$314,"<="&DATE(H5,12,31)) -> 988.58333 | J5: =I5/I4-1 -> -0.16628013 | L5: CAGR S&P500 Return- | M5: 20 Years | N5: =_xlfn.RRI(20,I9,I28) -> 0.081146307
B6: 36617 | C6: 1452.4 | D6: =C6/C5-1 -> -0.030828774 | H6: =H5+1 -> 2003 | I6: =AVERAGEIFS($C$3:$C$314,$B$3:$B$314,">="&DATE(H6,1,1),$B$3:$B$314,"<="&DATE(H6,12,31)) -> 967.925 | J6: =I6/I5-1 -> -0.020896906
B7: 36647 | C7: 1420.6 | D7: =C7/C6-1 -> -0.021894795 | H7: =H6+1 -> 2004 | I7: =AVERAGEIFS($C$3:$C$314,$B$3:$B$314,">="&DATE(H7,1,1),$B$3:$B$314,"<="&DATE(H7,12,31)) -> 1133.95 | J7: =I7/I6-1 -> 0.17152672 | L7: CAGR S&P500 Return- | M7: 15 Years | N7: =_xlfn.RRI(15,I14,I28) -> 0.11177256
B8: 36678 | C8: 1454.6 | D8: =C8/C7-1 -> 0.023933549 | H8: =H7+1 -> 2005 | I8: =AVERAGEIFS($C$3:$C$314,$B$3:$B$314,">="&DATE(H8,1,1),$B$3:$B$314,"<="&DATE(H8,12,31)) -> 1207.7667 | J8: =I8/I7-1 -> 0.065096933
B9: 36708 | C9: 1430.8 | D9: =C9/C8-1 -> -0.016361886 | H9: =H8+1 -> 2006 | I9: =AVERAGEIFS($C$3:$C$314,$B$3:$B$314,">="&DATE(H9,1,1),$B$3:$B$314,"<="&DATE(H9,12,31)) -> 1318.3 | J9: =I9/I8-1 -> 0.091518781 | L9: CAGR S&P500 Return- | M9: 10 Years | N9: =_xlfn.RRI(10,I19,I28) -> 0.11539339
B10: 36739 | C10: 1517.7 | D10: =C10/C9-1 -> 0.060735253 | H10: =H9+1 -> 2007 | I10: =AVERAGEIFS($C$3:$C$314,$B$3:$B$314,">="&DATE(H10,1,1),$B$3:$B$314,"<="&DATE(H10,12,31)) -> 1478.1 | J10: =I10/I9-1 -> 0.12121672
B11: 36770 | C11: 1436.5 | D11: =C11/C10-1 -> -0.05350201 | H11: =H10+1 -> 2008 | I11: =AVERAGEIFS($C$3:$C$314,$B$3:$B$314,">="&DATE(H11,1,1),$B$3:$B$314,"<="&DATE(H11,12,31)) -> 1215.2167 | J11: =I11/I10-1 -> -0.1778522 | L11: CAGR S&P500 Return- | M11: 7 years | N11: =_xlfn.RRI(7,I22,I28) -> 0.11453556
B12: 36800 | C12: 1429.4 | D12: =C12/C11-1 -> -0.0049425687 | H12: =H11+1 -> 2009 | I12: =AVERAGEIFS($C$3:$C$314,$B$3:$B$314,">="&DATE(H12,1,1),$B$3:$B$314,"<="&DATE(H12,12,31)) -> 948.51667 | J12: =I12/I11-1 -> -0.21946704
B13: 36831 | C13: 1315 | D13: =C13/C12-1 -> -0.080033581 | H13: =H12+1 -> 2010 | I13: =AVERAGEIFS($C$3:$C$314,$B$3:$B$314,">="&DATE(H13,1,1),$B$3:$B$314,"<="&DATE(H13,12,31)) -> 1130.675 | J13: =I13/I12-1 -> 0.19204547 | L13: CAGR S&P500 Return- | M13: 5 Years | N13: =_xlfn.RRI(5,I24,I28) -> 0.079635548
B14: 36861 | C14: 1320.3 | D14: =C14/C13-1 -> 0.0040304183 | H14: =H13+1 -> 2011 | I14: =AVERAGEIFS($C$3:$C$314,$B$3:$B$314,">="&DATE(H14,1,1),$B$3:$B$314,"<="&DATE(H14,12,31)) -> 1280.75 | J14: =I14/I13-1 -> 0.13273045
B15: 36892 | C15: 1366 | D15: =C15/C14-1 -> 0.034613345 | H15: =H14+1 -> 2012 | I15: =AVERAGEIFS($C$3:$C$314,$B$3:$B$314,">="&DATE(H15,1,1),$B$3:$B$314,"<="&DATE(H15,12,31)) -> 1386.5167 | J15: =I15/I14-1 -> 0.082581821
B16: 36923 | C16: 1239.9 | D16: =C16/C15-1 -> -0.092313324 | H16: =H15+1 -> 2013 | I16: =AVERAGEIFS($C$3:$C$314,$B$3:$B$314,">="&DATE(H16,1,1),$B$3:$B$314,"<="&DATE(H16,12,31)) -> 1652.2917 | J16: =I16/I15-1 -> 0.1916854
B17: 36951 | C17: 1160.3 | D17: =C17/C16-1 -> -0.064198726 | H17: =H16+1 -> 2014 | I17: =AVERAGEIFS($C$3:$C$314,$B$3:$B$314,">="&DATE(H17,1,1),$B$3:$B$314,"<="&DATE(H17,12,31)) -> 1944.415 | J17: =I17/I16-1 -> 0.17679889
B18: 36982 | C18: 1249.5 | D18: =C18/C17-1 -> 0.07687667 | H18: =H17+1 -> 2015 | I18: =AVERAGEIFS($C$3:$C$314,$B$3:$B$314,">="&DATE(H18,1,1),$B$3:$B$314,"<="&DATE(H18,12,31)) -> 2051.9292 | J18: =I18/I17-1 -> 0.055293837
B19: 37012 | C19: 1255.8 | D19: =C19/C18-1 -> 0.0050420168 | H19: =H18+1 -> 2016 | I19: =AVERAGEIFS($C$3:$C$314,$B$3:$B$314,">="&DATE(H19,1,1),$B$3:$B$314,"<="&DATE(H19,12,31)) -> 2105.8283 | J19: =I19/I18-1 -> 0.026267557
B20: 37043 | C20: 1224.4 | D20: =C20/C19-1 -> -0.025003982 | H20: =H19+1 -> 2017 | I20: =AVERAGEIFS($C$3:$C$314,$B$3:$B$314,">="&DATE(H20,1,1),$B$3:$B$314,"<="&DATE(H20,12,31)) -> 2465.2 | J20: =I20/I19-1 -> 0.17065573
B21: 37073 | C21: 1211.2 | D21: =C21/C20-1 -> -0.010780791 | H21: =H20+1 -> 2018 | I21: =AVERAGEIFS($C$3:$C$314,$B$3:$B$314,">="&DATE(H21,1,1),$B$3:$B$314,"<="&DATE(H21,12,31)) -> 2738.3958 | J21: =I21/I20-1 -> 0.11082096
B22: 37104 | C22: 1133.6 | D22: =C22/C21-1 -> -0.064068692 | H22: =H21+1 -> 2019 | I22: =AVERAGEIFS($C$3:$C$314,$B$3:$B$314,">="&DATE(H22,1,1),$B$3:$B$314,"<="&DATE(H22,12,31)) -> 2937.9617 | J22: =I22/I21-1 -> 0.072876912
B23: 37135 | C23: 1040.9 | D23: =C23/C22-1 -> -0.081774876 | H23: =H22+1 -> 2020 | I23: =AVERAGEIFS($C$3:$C$314,$B$3:$B$314,">="&DATE(H23,1,1),$B$3:$B$314,"<="&DATE(H23,12,31)) -> 3216.9542 | J23: =I23/I22-1 -> 0.094961246
B24: 37165 | C24: 1059.8 | D24: =C24/C23-1 -> 0.018157364 | H24: =H23+1 -> 2021 | I24: =AVERAGEIFS($C$3:$C$314,$B$3:$B$314,">="&DATE(H24,1,1),$B$3:$B$314,"<="&DATE(H24,12,31)) -> 4278.7583 | J24: =I24/I23-1 -> 0.33006506
B25: 37196 | C25: 1139.5 | D25: =C25/C24-1 -> 0.075202868 | H25: =H24+1 -> 2022 | I25: =AVERAGEIFS($C$3:$C$314,$B$3:$B$314,">="&DATE(H25,1,1),$B$3:$B$314,"<="&DATE(H25,12,31)) -> 4077.655 | J25: =I25/I24-1 -> -0.047000395
... B28: 37288 | C28: 1106.7 | D28: =C28/C27-1 -> -0.02079278 | H28: =H27+1 -> 2025 | I28: =AVERAGEIFS($C$3:$C$314,$B$3:$B$314,">="&DATE(H28,1,1),$B$3:$B$314,"<="&DATE(H28,12,31)) -> 6276.2992 | J28: =I28/I27-1 -> 0.1494599
B29: 37316 | C29: 1147.4 | D29: =C29/C28-1 -> 0.036776001
B30: 37347 | C30: 1076.9 | D30: =C30/C29-1 -> -0.061443263
B31: 37377 | C31: 1067.1 | D31: =C31/C30-1 -> -0.009100195
B32: 37408 | C32: 989.8 | D32: =C32/C31-1 -> -0.072439322
B33: 37438 | C33: 911.6 | D33: =C33/C32-1 -> -0.07900586
B34: 37469 | C34: 916.1 | D34: =C34/C33-1 -> 0.0049363756
B35: 37500 | C35: 815.3 | D35: =C35/C34-1 -> -0.11003166
B36: 37530 | C36: 885.8 | D36: =C36/C35-1 -> 0.086471238
B37: 37561 | C37: 936.3 | D37: =C37/C36-1 -> 0.057010612
B38: 37591 | C38: 879.8 | D38: =C38/C37-1 -> -0.060343907
B39: 37622 | C39: 855.7 | D39: =C39/C38-1 -> -0.027392589
B40: 37653 | C40: 841.1 | D40: =C40/C39-1 -> -0.017062054
... B314: 45992 | C314: 6845.61 | D314: =C314/C313-1 -> -0.0005080967
B317: Source: Investing.com

Sheet ERP Historical
B2: Year | C2: Beginning Year ERP
B3: 2003 | C3: 0.0488
B4: =B3+1 -> 2004 | C4: 0.0514 | F4: Average ERP - | G4: 15 Years | H4: =AVERAGE(C11:C25) -> 0.0405
B5: =B4+1 -> 2005 | C5: 0.0346
B6: =B5+1 -> 2006 | C6: 0.0353 | F6: Average ERP - | G6: 7 Years | H6: =AVERAGE(C19:C25) -> 0.033657143
B7: =B6+1 -> 2007 | C7: 0.034
B8: =B7+1 -> 2008 | C8: 0.046 | F8: Average ERP - | G8: 5 Years | H8: =AVERAGE(C21:C25) -> 0.02986
B9: =B8+1 -> 2009 | C9: 0.0719
B10: =B9+1 -> 2010 | C10: 0.0427 | F10: Average ERP - | G10: 3 Years | H10: =AVERAGE(C23:C25) -> 0.0266
B11: =B10+1 -> 2011 | C11: 0.0473
B12: =B11+1 -> 2012 | C12: 0.0605 | F12: Average ERP - | G12: Latest | H12: =C25 -> 0.0198
B13: =B12+1 -> 2013 | C13: 0.0546
B14: =B13+1 -> 2014 | C14: 0.0435
B15: =B14+1 -> 2015 | C15: 0.0468
B16: =B15+1 -> 2016 | C16: 0.0493
B17: =B16+1 -> 2017 | C17: 0.0373
B18: =B17+1 -> 2018 | C18: 0.0326
B19: =B18+1 -> 2019 | C19: 0.0449
B20: =B19+1 -> 2020 | C20: 0.0414
B21: =B20+1 -> 2021 | C21: 0.0357
B22: =B21+1 -> 2022 | C22: 0.0338
B23: =B22+1 -> 2023 | C23: 0.0324
B24: =B23+1 -> 2024 | C24: 0.0276
B25: 2025 | C25: 0.0198
B27: Source : Market Premia

Sheet Rf Historical
B2: Date | C2: Price | F2: Year | G2: 10Y Bond Average Rate
B3: 25600 | C3: 0.0724 | F3: 1970 | G3: =AVERAGEIFS($C$3:$C$672,$B$3:$B$672,">="&DATE(F3,1,1),$B$3:$B$672,"<="&DATE(F3,12,31)) -> 0.073081818
B4: 25628 | C4: 0.0707 | F4: =F3+1 -> 1971 | G4: =AVERAGEIFS($C$3:$C$672,$B$3:$B$672,">="&DATE(F4,1,1),$B$3:$B$672,"<="&DATE(F4,12,31)) -> 0.061591667 | I4: Average Rate- | J4: 50 Yrs | K4: =AVERAGE(G9:G58) -> 0.058135382
B5: 25659 | C5: 0.0739 | F5: =F4+1 -> 1972 | G5: =AVERAGEIFS($C$3:$C$672,$B$3:$B$672,">="&DATE(F5,1,1),$B$3:$B$672,"<="&DATE(F5,12,31)) -> 0.0621
B6: 25689 | C6: 0.0791 | F6: =F5+1 -> 1973 | G6: =AVERAGEIFS($C$3:$C$672,$B$3:$B$672,">="&DATE(F6,1,1),$B$3:$B$672,"<="&DATE(F6,12,31)) -> 0.068425 | I6: Average Rate- | J6: 30 Yrs | K6: =AVERAGE(G29:G58) -> 0.036414859
B7: 25720 | C7: 0.0784 | F7: =F6+1 -> 1974 | G7: =AVERAGEIFS($C$3:$C$672,$B$3:$B$672,">="&DATE(F7,1,1),$B$3:$B$672,"<="&DATE(F7,12,31)) -> 0.075575
B8: 25750 | C8: 0.0746 | F8: =F7+1 -> 1975 | G8: =AVERAGEIFS($C$3:$C$672,$B$3:$B$672,">="&DATE(F8,1,1),$B$3:$B$672,"<="&DATE(F8,12,31)) -> 0.079875 | I8: Average Rate- | J8: 20 Yrs | K8: =AVERAGE(G39:G58) -> 0.028792288
B9: 25781 | C9: 0.0753 | F9: =F8+1 -> 1976 | G9: =AVERAGEIFS($C$3:$C$672,$B$3:$B$672,">="&DATE(F9,1,1),$B$3:$B$672,"<="&DATE(F9,12,31)) -> 0.076116667
B10: 25812 | C10: 0.0739 | F10: =F9+1 -> 1977 | G10: =AVERAGEIFS($C$3:$C$672,$B$3:$B$672,">="&DATE(F10,1,1),$B$3:$B$672,"<="&DATE(F10,12,31)) -> 0.074191667 | I10: Average Rate- | J10: 15 Yrs | K10: =AVERAGE(G44:G58) -> 0.025496106
B11: 25842 | C11: 0.0733 | F11: =F10+1 -> 1978 | G11: =AVERAGEIFS($C$3:$C$672,$B$3:$B$672,">="&DATE(F11,1,1),$B$3:$B$672,"<="&DATE(F11,12,31)) -> 0.0841
B12: 25873 | C12: 0.0684 | F12: =F11+1 -> 1979 | G12: =AVERAGEIFS($C$3:$C$672,$B$3:$B$672,">="&DATE(F12,1,1),$B$3:$B$672,"<="&DATE(F12,12,31)) -> 0.094425 | I12: Average Rate- | J12: 7 Yrs | K12: =AVERAGE(G52:G58) -> 0.028277132
B13: 25903 | C13: 0.0639 | F13: =F12+1 -> 1980 | G13: =AVERAGEIFS($C$3:$C$672,$B$3:$B$672,">="&DATE(F13,1,1),$B$3:$B$672,"<="&DATE(F13,12,31)) -> 0.11413583
B14: 25934 | C14: 0.0624 | F14: =F13+1 -> 1981 | G14: =AVERAGEIFS($C$3:$C$672,$B$3:$B$672,">="&DATE(F14,1,1),$B$3:$B$672,"<="&DATE(F14,12,31)) -> 0.14012917 | I14: Average Rate- | J14: 5 Yrs | K14: =AVERAGE(G54:G58) -> 0.033786985
B15: 25965 | C15: 0.0611 | F15: =F14+1 -> 1982 | G15: =AVERAGEIFS($C$3:$C$672,$B$3:$B$672,">="&DATE(F15,1,1),$B$3:$B$672,"<="&DATE(F15,12,31)) -> 0.1294825
B16: 25993 | C16: 0.057 | F16: =F15+1 -> 1983 | G16: =AVERAGEIFS($C$3:$C$672,$B$3:$B$672,">="&DATE(F16,1,1),$B$3:$B$672,"<="&DATE(F16,12,31)) -> 0.11136917 | I16: Average Rate- | J16: Latest | K16: =G58 -> 0.042479091
B17: 26024 | C17: 0.0583 | F17: =F16+1 -> 1984 | G17: =AVERAGEIFS($C$3:$C$672,$B$3:$B$672,">="&DATE(F17,1,1),$B$3:$B$672,"<="&DATE(F17,12,31)) -> 0.12481333
B18: 26054 | C18: 0.0639 | F18: =F17+1 -> 1985 | G18: =AVERAGEIFS($C$3:$C$672,$B$3:$B$672,">="&DATE(F18,1,1),$B$3:$B$672,"<="&DATE(F18,12,31)) -> 0.10533583
B19: 26085 | C19: 0.0652 | F19: =F18+1 -> 1986 | G19: =AVERAGEIFS($C$3:$C$672,$B$3:$B$672,">="&DATE(F19,1,1),$B$3:$B$672,"<="&DATE(F19,12,31)) -> 0.0756325
B20: 26115 | C20: 0.0673 | F20: =F19+1 -> 1987 | G20: =AVERAGEIFS($C$3:$C$672,$B$3:$B$672,">="&DATE(F20,1,1),$B$3:$B$672,"<="&DATE(F20,12,31)) -> 0.0839725
B21: 26146 | C21: 0.0658 | F21: =F20+1 -> 1988 | G21: =AVERAGEIFS($C$3:$C$672,$B$3:$B$672,">="&DATE(F21,1,1),$B$3:$B$672,"<="&DATE(F21,12,31)) -> 0.088300833
B22: 26177 | C22: 0.0614 | F22: =F21+1 -> 1989 | G22: =AVERAGEIFS($C$3:$C$672,$B$3:$B$672,">="&DATE(F22,1,1),$B$3:$B$672,"<="&DATE(F22,12,31)) -> 0.084510833
B23: 26207 | C23: 0.0593 | F23: =F22+1 -> 1990 | G23: =AVERAGEIFS($C$3:$C$672,$B$3:$B$672,">="&DATE(F23,1,1),$B$3:$B$672,"<="&DATE(F23,12,31)) -> 0.085555833
B24: 26238 | C24: 0.0581 | F24: =F23+1 -> 1991 | G24: =AVERAGEIFS($C$3:$C$672,$B$3:$B$672,">="&DATE(F24,1,1),$B$3:$B$672,"<="&DATE(F24,12,31)) -> 0.077799167
B25: 26268 | C25: 0.0593 | F25: =F24+1 -> 1992 | G25: =AVERAGEIFS($C$3:$C$672,$B$3:$B$672,">="&DATE(F25,1,1),$B$3:$B$672,"<="&DATE(F25,12,31)) -> 0.0701225
B26: 26299 | C26: 0.0595 | F26: =F25+1 -> 1993 | G26: =AVERAGEIFS($C$3:$C$672,$B$3:$B$672,">="&DATE(F26,1,1),$B$3:$B$672,"<="&DATE(F26,12,31)) -> 0.05829
B27: 26330 | C27: 0.0608 | F27: =F26+1 -> 1994 | G27: =AVERAGEIFS($C$3:$C$672,$B$3:$B$672,">="&DATE(F27,1,1),$B$3:$B$672,"<="&DATE(F27,12,31)) -> 0.071235
B28: 26359 | C28: 0.0607 | F28: =F27+1 -> 1995 | G28: =AVERAGEIFS($C$3:$C$672,$B$3:$B$672,">="&DATE(F28,1,1),$B$3:$B$672,"<="&DATE(F28,12,31)) -> 0.064805
... B58: 27273 | C58: 0.0804 | F58: =F57+1 -> 2025 | G58: =AVERAGEIFS($C$3:$C$672,$B$3:$B$672,">="&DATE(F58,1,1),$B$3:$B$672,"<="&DATE(F58,12,31)) -> 0.042479091
B59: 27303 | C59: 0.079
B60: 27334 | C60: 0.0768
B61: 27364 | C61: 0.0743
B62: 27395 | C62: 0.075
B63: 27426 | C63: 0.0739
B64: 27454 | C64: 0.0773
B65: 27485 | C65: 0.0823
B66: 27515 | C66: 0.0806
B67: 27546 | C67: 0.0786
B68: 27576 | C68: 0.0806
B69: 27607 | C69: 0.084
B70: 27638 | C70: 0.0843
...
